Workbook

Sheet Formato
B1: Favor de NO modificar las celdas en color azul, solo seleccionar.
B2: Las celdas en color gris son condicionados según centro de costos y estatus de gasto
B4: FORMATO DE ANALISIS DE GASTOS DE CASETAS
B6: Nombre Departamento | D6: Consumer Bussiness Planning & Adm
B7: Código de Centro de Costos | D7: =VLOOKUP(D6,'Estructura cecos Jul2024'!B5:E50,4,0) -> 470401
B8: Periodo de Facturación
B10: Clave de Empleado | C10: Nombre de Empleados | D10: Num de Cruces | E10: Monto de Total de Casetas | F10: Aceptado (Si o No) | G10: Cuenta Contable
F11: No | G11: =IF(F11="Si",VLOOKUP($D$7,'Estructura cecos Jul2024'!$E$5:$R$50,14,0),'Estructura cecos Jul2024'!$I$2) -> ACU-041-999999-11991002-999-ZZ-000-0000-000
F12: Seleccionar | G12: =IF(F12="Si",VLOOKUP($D$7,'Estructura cecos Jul2024'!$E$5:$R$50,14,0),'Estructura cecos Jul2024'!$I$2) -> ACU-041-999999-11991002-999-ZZ-000-0000-000
F13: Seleccionar | G13: =IF(F13="Si",VLOOKUP($D$7,'Estructura cecos Jul2024'!$E$5:$R$50,14,0),'Estructura cecos Jul2024'!$I$2) -> ACU-041-999999-11991002-999-ZZ-000-0000-000
F14: Seleccionar | G14: =IF(F14="Si",VLOOKUP($D$7,'Estructura cecos Jul2024'!$E$5:$R$50,14,0),'Estructura cecos Jul2024'!$I$2) -> ACU-041-999999-11991002-999-ZZ-000-0000-000
F15: Seleccionar | G15: =IF(F15="Si",VLOOKUP($D$7,'Estructura cecos Jul2024'!$E$5:$R$50,14,0),'Estructura cecos Jul2024'!$I$2) -> ACU-041-999999-11991002-999-ZZ-000-0000-000
F16: Seleccionar | G16: =IF(F16="Si",VLOOKUP($D$7,'Estructura cecos Jul2024'!$E$5:$R$50,14,0),'Estructura cecos Jul2024'!$I$2) -> ACU-041-999999-11991002-999-ZZ-000-0000-000
F17: Seleccionar | G17: =IF(F17="Si",VLOOKUP($D$7,'Estructura cecos Jul2024'!$E$5:$R$50,14,0),'Estructura cecos Jul2024'!$I$2) -> ACU-041-999999-11991002-999-ZZ-000-0000-000
F18: Seleccionar | G18: =IF(F18="Si",VLOOKUP($D$7,'Estructura cecos Jul2024'!$E$5:$R$50,14,0),'Estructura cecos Jul2024'!$I$2) -> ACU-041-999999-11991002-999-ZZ-000-0000-000
F19: Seleccionar | G19: =IF(F19="Si",VLOOKUP($D$7,'Estructura cecos Jul2024'!$E$5:$R$50,14,0),'Estructura cecos Jul2024'!$I$2) -> ACU-041-999999-11991002-999-ZZ-000-0000-000
F20: Seleccionar | G20: =IF(F20="Si",VLOOKUP($D$7,'Estructura cecos Jul2024'!$E$5:$R$50,14,0),'Estructura cecos Jul2024'!$I$2) -> ACU-041-999999-11991002-999-ZZ-000-0000-000
F21: Seleccionar | G21: =IF(F21="Si",VLOOKUP($D$7,'Estructura cecos Jul2024'!$E$5:$R$50,14,0),'Estructura cecos Jul2024'!$I$2) -> ACU-041-999999-11991002-999-ZZ-000-0000-000
F22: Seleccionar | G22: =IF(F22="Si",VLOOKUP($D$7,'Estructura cecos Jul2024'!$E$5:$R$50,14,0),'Estructura cecos Jul2024'!$I$2) -> ACU-041-999999-11991002-999-ZZ-000-0000-000
... F29: Seleccionar | G29: =IF(F29="Si",VLOOKUP($D$7,'Estructura cecos Jul2024'!$E$5:$R$50,14,0),'Estructura cecos Jul2024'!$I$2) -> ACU-041-999999-11991002-999-ZZ-000-0000-000
D30: 1 | F30: Seleccionar | G30: =IF(F30="Si",VLOOKUP($D$7,'Estructura cecos Jul2024'!$E$5:$R$50,14,0),'Estructura cecos Jul2024'!$I$2) -> ACU-041-999999-11991002-999-ZZ-000-0000-000
F31: Seleccionar | G31: =IF(F31="Si",VLOOKUP($D$7,'Estructura cecos Jul2024'!$E$5:$R$50,14,0),'Estructura cecos Jul2024'!$I$2) -> ACU-041-999999-11991002-999-ZZ-000-0000-000
F32: Seleccionar | G32: =IF(F32="Si",VLOOKUP($D$7,'Estructura cecos Jul2024'!$E$5:$R$50,14,0),'Estructura cecos Jul2024'!$I$2) -> ACU-041-999999-11991002-999-ZZ-000-0000-000
F33: Seleccionar | G33: =IF(F33="Si",VLOOKUP($D$7,'Estructura cecos Jul2024'!$E$5:$R$50,14,0),'Estructura cecos Jul2024'!$I$2) -> ACU-041-999999-11991002-999-ZZ-000-0000-000
F34: Seleccionar | G34: =IF(F34="Si",VLOOKUP($D$7,'Estructura cecos Jul2024'!$E$5:$R$50,14,0),'Estructura cecos Jul2024'!$I$2) -> ACU-041-999999-11991002-999-ZZ-000-0000-000
F35: Seleccionar | G35: =IF(F35="Si",VLOOKUP($D$7,'Estructura cecos Jul2024'!$E$5:$R$50,14,0),'Estructura cecos Jul2024'!$I$2) -> ACU-041-999999-11991002-999-ZZ-000-0000-000
C36: Total | D36: =SUM(D11:D35) -> 1 | E36: =SUM(E11:E35) -> 0
B39: Autorizo
C40: Gerente
B41: Nombre:

Sheet Opciones
B3: Aceptado
B4: Seleccionar
B5: Si
B6: No

Sheet Estructura cecos Jul2024
B1: JULY 2024
B2: COST CENTER STRUCTURE | I2: ACU-041-999999-11991002-999-ZZ-000-0000-000
B3: Area | C3: RH | D3: S21 | E3: ARCS | G3: ARCS | I3: Cia | J3: Branch | K3: Cost Center | L3: Cuenta | M3: Channel Code | N3: GL Product | O3: Aff Code | P3: Project Code | Q3: TBD
E4: 1 | F4: 2 | G4: 3 | H4: 4 | I4: 5 | J4: 6 | K4: 7 | L4: 8 | M4: 9 | N4: 10 | O4: 11 | P4: 12 | Q4: 13 | R4: 14
B5: Corporate Communications | C5: AA030 / 493001 | D5: AA030 | E5: 493001 | G5: 999 | H5: ADMIN | I5: ACU | J5: 041 | K5: =E5 -> 493001 | L5: 63101503 | M5: =G5 -> 999 | N5: ZZ | O5: 000 | P5: 0000 | Q5: 000 | R5: =CONCATENATE(I5,"-",J5,"-",K5,"-",L5,"-",M5,"-",N5,"-",O5,"-",P5,"-",Q5) -> ACU-041-493001-63101503-999-ZZ-000-0000-000
B6: General Affairs | C6: AA220 / 492201 | D6: AA220 | E6: 492201 | G6: 999 | I6: ACU | J6: 041 | K6: =E6 -> 492201 | L6: 63101503 | M6: =G6 -> 999 | N6: ZZ | O6: 000 | P6: 0000 | Q6: 000 | R6: =CONCATENATE(I6,"-",J6,"-",K6,"-",L6,"-",M6,"-",N6,"-",O6,"-",P6,"-",Q6) -> ACU-041-492201-63101503-999-ZZ-000-0000-000
B7: Human Resources | C7: AA210 / 492101 | D7: AA210 | E7: 492101 | G7: 999 | I7: ACU | J7: 041 | K7: =E7 -> 492101 | L7: 63101503 | M7: =G7 -> 999 | N7: ZZ | O7: 000 | P7: 0000 | Q7: 000 | R7: =CONCATENATE(I7,"-",J7,"-",K7,"-",L7,"-",M7,"-",N7,"-",O7,"-",P7,"-",Q7) -> ACU-041-492101-63101503-999-ZZ-000-0000-000
B8: IT | C8: AA130 / 497001 | D8: AA130 | E8: 497001 | G8: 999 | I8: ACU | J8: 041 | K8: =E8 -> 497001 | L8: 63101503 | M8: =G8 -> 999 | N8: ZZ | O8: 000 | P8: 0000 | Q8: 000 | R8: =CONCATENATE(I8,"-",J8,"-",K8,"-",L8,"-",M8,"-",N8,"-",O8,"-",P8,"-",Q8) -> ACU-041-497001-63101503-999-ZZ-000-0000-000
B9: Legal | C9: AA020 / 496101 | D9: AA020 | E9: 496101 | G9: 999 | I9: ACU | J9: 041 | K9: =E9 -> 496101 | L9: 63101503 | M9: =G9 -> 999 | N9: ZZ | O9: 000 | P9: 0000 | Q9: 000 | R9: =CONCATENATE(I9,"-",J9,"-",K9,"-",L9,"-",M9,"-",N9,"-",O9,"-",P9,"-",Q9) -> ACU-041-496101-63101503-999-ZZ-000-0000-000
B10: Logistics | C10: AA140 / 495003 | D10: AA140 | E10: 495003 | G10: 999 | I10: ACU | J10: 041 | K10: =E10 -> 495003 | L10: 63101503 | M10: =G10 -> 999 | N10: ZZ | O10: 000 | P10: 0000 | Q10: 000 | R10: =CONCATENATE(I10,"-",J10,"-",K10,"-",L10,"-",M10,"-",N10,"-",O10,"-",P10,"-",Q10) -> ACU-041-495003-63101503-999-ZZ-000-0000-000
B11: Traffic | C11: AA140 / 495003 | D11: AA150 | E11: 495002 | G11: 999 | I11: ACU | J11: 041 | K11: =E11 -> 495002 | L11: 63101503 | M11: =G11 -> 999 | N11: ZZ | O11: 000 | P11: 0000 | Q11: 000 | R11: =CONCATENATE(I11,"-",J11,"-",K11,"-",L11,"-",M11,"-",N11,"-",O11,"-",P11,"-",Q11) -> ACU-041-495002-63101503-999-ZZ-000-0000-000
B12: Procurement | C12: AA230 / 492301 | D12: AA230 | E12: 492301 | G12: 999 | I12: ACU | J12: 041 | K12: =E12 -> 492301 | L12: 63101503 | M12: =G12 -> 999 | N12: ZZ | O12: 000 | P12: 0000 | Q12: 000 | R12: =CONCATENATE(I12,"-",J12,"-",K12,"-",L12,"-",M12,"-",N12,"-",O12,"-",P12,"-",Q12) -> ACU-041-492301-63101503-999-ZZ-000-0000-000
B13: Accounting/Budget and Treasury | C13: AA110 / 494101 | D13: AA110 | E13: 494101 | G13: 999 | I13: ACU | J13: 041 | K13: =E13 -> 494101 | L13: 63101503 | M13: =G13 -> 999 | N13: ZZ | O13: 000 | P13: 0000 | Q13: 000 | R13: =CONCATENATE(I13,"-",J13,"-",K13,"-",L13,"-",M13,"-",N13,"-",O13,"-",P13,"-",Q13) -> ACU-041-494101-63101503-999-ZZ-000-0000-000
B14: Credit and Collection | C14: AA120 / 496102 | D14: AA120 | E14: 496102 | G14: 999 | I14: ACU | J14: 041 | K14: =E14 -> 496102 | L14: 63101503 | M14: =G14 -> 999 | N14: ZZ | O14: 000 | P14: 0000 | Q14: 000 | R14: =CONCATENATE(I14,"-",J14,"-",K14,"-",L14,"-",M14,"-",N14,"-",O14,"-",P14,"-",Q14) -> ACU-041-496102-63101503-999-ZZ-000-0000-000
B15: Financial Services | C15: AA160 / 495012 | D15: AA160 | E15: 495012 | G15: 999 | I15: ACU | J15: 041 | K15: =E15 -> 495012 | L15: 63101503 | M15: =G15 -> 999 | N15: ZZ | O15: 000 | P15: 0000 | Q15: 000 | R15: =CONCATENATE(I15,"-",J15,"-",K15,"-",L15,"-",M15,"-",N15,"-",O15,"-",P15,"-",Q15) -> ACU-041-495012-63101503-999-ZZ-000-0000-000
B16: Internal Audit | C16: AA050 / 494301 | D16: AA050 | E16: 494301 | G16: 999 | I16: ACU | J16: 041 | K16: =E16 -> 494301 | L16: 63101503 | M16: =G16 -> 999 | N16: ZZ | O16: 000 | P16: 0000 | Q16: 000 | R16: =CONCATENATE(I16,"-",J16,"-",K16,"-",L16,"-",M16,"-",N16,"-",O16,"-",P16,"-",Q16) -> ACU-041-494301-63101503-999-ZZ-000-0000-000
B17: Presidency | C17: AA010 / 490001 | D17: AA010 | E17: 490001 | G17: 999 | I17: ACU | J17: 041 | K17: =E17 -> 490001 | L17: 63101503 | M17: =G17 -> 999 | N17: ZZ | O17: 000 | P17: 0000 | Q17: 000 | R17: =CONCATENATE(I17,"-",J17,"-",K17,"-",L17,"-",M17,"-",N17,"-",O17,"-",P17,"-",Q17) -> ACU-041-490001-63101503-999-ZZ-000-0000-000
B18: Leasing Revenue | C18: AA300 / 414002 | D18: AA300 | E18: 414002 | G18: 244 | H18: ADM | I18: ACU | J18: 041 | K18: =E18 -> 414002 | L18: 63101503 | M18: =G18 -> 244 | N18: 96 | O18: 000 | P18: 0000 | Q18: 000 | R18: =CONCATENATE(I18,"-",J18,"-",K18,"-",L18,"-",M18,"-",N18,"-",O18,"-",P18,"-",Q18) -> ACU-041-414002-63101503-244-96-000-0000-000
B19: Dealers Sales | C19: AV210 / 411001 | D19: AV210 | E19: 411001 | G19: 208 | H19: Dealer | I19: ACU | J19: 041 | K19: =E19 -> 411001 | L19: 63101503 | M19: =G19 -> 208 | N19: DH | O19: 000 | P19: 0000 | Q19: 000 | R19: =CONCATENATE(I19,"-",J19,"-",K19,"-",L19,"-",M19,"-",N19,"-",O19,"-",P19,"-",Q19) -> ACU-041-411001-63101503-208-DH-000-0000-000
B20: PPS Sales | C20: KV700 / 411301 | D20: KV700 | E20: 411301 | G20: 161 | H20: PPS Sales | I20: ACU | J20: 041 | K20: =E20 -> 411301 | L20: 63101503 | M20: =G20 -> 161 | N20: 5B | O20: 000 | P20: 0000 | Q20: 000 | R20: =CONCATENATE(I20,"-",J20,"-",K20,"-",L20,"-",M20,"-",N20,"-",O20,"-",P20,"-",Q20) -> ACU-041-411301-63101503-161-5B-000-0000-000
B21: Enterprise Business Solutions Direct Sales | C21: AV240 / 411307 | D21: AV240 | E21: 411307 | G21: 101 | H21: EBSS | I21: ACU | J21: 041 | K21: =E21 -> 411307 | L21: 63101503 | M21: =G21 -> 101 | N21: DH | O21: 000 | P21: 0000 | Q21: 000 | R21: =CONCATENATE(I21,"-",J21,"-",K21,"-",L21,"-",M21,"-",N21,"-",O21,"-",P21,"-",Q21) -> ACU-041-411307-63101503-101-DH-000-0000-000
B22: Business Printing Sales Mktg | C22: AV340 / 413116 | D22: AV340 | E22: 413116 | G22: 155 | H22: North Zone BICG | I22: ACU | J22: 041 | K22: =E22 -> 413116 | L22: 63101503 | M22: =G22 -> 155 | O22: 000 | P22: 0000 | Q22: 000 | R22: =CONCATENATE(I22,"-",J22,"-",K22,"-",L22,"-",M22,"-",N22,"-",O22,"-",P22,"-",Q22) -> ACU-041-413116-63101503-155--000-0000-000
B23: Managed Delivery Services | C23: AV260 / 411406 | D23: AV260 | E23: 411406 | G23: 998 | H23: ADMIN BICG | I23: ACU | J23: 041 | K23: =E23 -> 411406 | L23: 63101503 | M23: =G23 -> 998 | O23: 000 | P23: 0000 | Q23: 000 | R23: =CONCATENATE(I23,"-",J23,"-",K23,"-",L23,"-",M23,"-",N23,"-",O23,"-",P23,"-",Q23) -> ACU-041-411406-63101503-998--000-0000-000
B24: RFB Service | C24: AV270 / 411104 | D24: AV270 | E24: 411104 | G24: 998 | I24: ACU | J24: 041 | K24: =E24 -> 411104 | L24: 63101503 | M24: =G24 -> 998 | N24: DH | O24: 000 | P24: 0000 | Q24: 000 | R24: =CONCATENATE(I24,"-",J24,"-",K24,"-",L24,"-",M24,"-",N24,"-",O24,"-",P24,"-",Q24) -> ACU-041-411104-63101503-998-DH-000-0000-000
B25: Care Center | C25: AV280 / 411002 | D25: AV280 | E25: 411002 | G25: 998 | I25: ACU | J25: 041 | K25: =E25 -> 411002 | L25: 63101503 | M25: =G25 -> 998 | N25: DH | O25: 000 | P25: 0000 | Q25: 000 | R25: =CONCATENATE(I25,"-",J25,"-",K25,"-",L25,"-",M25,"-",N25,"-",O25,"-",P25,"-",Q25) -> ACU-041-411002-63101503-998-DH-000-0000-000
B26: Direct Service (OBS) | C26: AV510 / 421101 | D26: AV510 | E26: 421101 | G26: 998 | I26: ACU | J26: 041 | K26: =E26 -> 421101 | L26: 63101503 | M26: =G26 -> 998 | N26: DH | O26: 000 | P26: 0000 | Q26: 000 | R26: =CONCATENATE(I26,"-",J26,"-",K26,"-",L26,"-",M26,"-",N26,"-",O26,"-",P26,"-",Q26) -> ACU-041-421101-63101503-998-DH-000-0000-000
B27: Direct Service (PPS) | C27: AV540 / 426006 | D27: AV540 | E27: 426006 | G27: 998 | I27: ACU | J27: 041 | K27: =E27 -> 426006 | L27: 63101503 | M27: =G27 -> 998 | N27: 5B | O27: 000 | P27: 0000 | Q27: 000 | R27: =CONCATENATE(I27,"-",J27,"-",K27,"-",L27,"-",M27,"-",N27,"-",O27,"-",P27,"-",Q27) -> ACU-041-426006-63101503-998-5B-000-0000-000
B28: Service Administration | C28: AV500 / 426011 | D28: AV500 | E28: 426011 | G28: 998 | I28: ACU | J28: 041 | K28: =E28 -> 426011 | L28: 63101503 | M28: =G28 -> 998 | N28: DH | O28: 000 | P28: 0000 | Q28: 000 | R28: =CONCATENATE(I28,"-",J28,"-",K28,"-",L28,"-",M28,"-",N28,"-",O28,"-",P28,"-",Q28) -> ACU-041-426011-63101503-998-DH-000-0000-000
B29: Solutions Technical support | C29: AV250 / 426012 | D29: AV250 | E29: 426012 | G29: 998 | I29: ACU | J29: 041 | K29: =E29 -> 426012 | L29: 63101503 | M29: =G29 -> 998 | N29: 96 | O29: 000 | P29: 0000 | Q29: 000 | R29: =CONCATENATE(I29,"-",J29,"-",K29,"-",L29,"-",M29,"-",N29,"-",O29,"-",P29,"-",Q29) -> ACU-041-426012-63101503-998-96-000-0000-000
B30: Product Planning & Mktg.OBS | C30: AV220 / 461101 | D30: AV220 | E30: 461101 | G30: 998 | I30: ACU | J30: 041 | K30: =E30 -> 461101 | L30: 63101503 | M30: =G30 -> 998 | N30: DH | O30: 000 | P30: 0000 | Q30: 000 | R30: =CONCATENATE(I30,"-",J30,"-",K30,"-",L30,"-",M30,"-",N30,"-",O30,"-",P30,"-",Q30) -> ACU-041-461101-63101503-998-DH-000-0000-000
B31: Product Planning & Mktg.PPS | C31: AV320 / 411302 | D31: AV320 | E31: 411302 | G31: 998 | I31: ACU | J31: 041 | K31: =E31 -> 411302 | L31: 63101503 | M31: =G31 -> 998 | N31: 5B | O31: 000 | P31: 0000 | Q31: 000 | R31: =CONCATENATE(I31,"-",J31,"-",K31,"-",L31,"-",M31,"-",N31,"-",O31,"-",P31,"-",Q31) -> ACU-041-411302-63101503-998-5B-000-0000-000
B32: Business Planning Services | C32: AV230 / 470001 | D32: AV230 | E32: 470001 | G32: 998 | I32: ACU | J32: 041 | K32: =E32 -> 470001 | L32: 63101503 | M32: =G32 -> 998 | N32: DH | O32: 000 | P32: 0000 | Q32: 000 | R32: =CONCATENATE(I32,"-",J32,"-",K32,"-",L32,"-",M32,"-",N32,"-",O32,"-",P32,"-",Q32) -> ACU-041-470001-63101503-998-DH-000-0000-000
B33: Strategic Analysis & Opp Mgmt | C33: AV310 / 426014 | D33: AV310 | E33: 426014 | G33: 998 | I33: ACU | J33: 041 | K33: =E33 -> 426014 | L33: 63101503 | M33: =G33 -> 998 | O33: 000 | P33: 0000 | Q33: 000 | R33: =CONCATENATE(I33,"-",J33,"-",K33,"-",L33,"-",M33,"-",N33,"-",O33,"-",P33,"-",Q33) -> ACU-041-426014-63101503-998--000-0000-000
B34: Retail Sales | C34: AV620 / 411403 | D34: AV620 | E34: 411403 | F34: ok | G34: 141 | H34: Retail | I34: ACU | J34: 041 | K34: =E34 -> 411403 | L34: 63101503 | M34: =G34 -> 141 | N34: AA | O34: 000 | P34: 0000 | Q34: 000 | R34: =CONCATENATE(I34,"-",J34,"-",K34,"-",L34,"-",M34,"-",N34,"-",O34,"-",P34,"-",Q34) -> ACU-041-411403-63101503-141-AA-000-0000-000
B35: Photoshop Sales | C35: AV630 / 411401 | D35: AV630 | E35: 411401 | F35: ok | G35: 142 | H35: Photoshop | I35: ACU | J35: 041 | K35: =E35 -> 411401 | L35: 63101503 | M35: =G35 -> 142 | N35: AA | O35: 000 | P35: 0000 | Q35: 000 | R35: =CONCATENATE(I35,"-",J35,"-",K35,"-",L35,"-",M35,"-",N35,"-",O35,"-",P35,"-",Q35) -> ACU-041-411401-63101503-142-AA-000-0000-000
B36: Wholesaler Sales | C36: AV640 / 411003 | D36: AV640 | E36: 411003 | F36: ok | G36: =TEXT(210,0) -> 210 | H36: Wholesaler | I36: ACU | J36: 041 | K36: =E36 -> 411003 | L36: 63101503 | M36: =G36 -> 210 | N36: UO | O36: 000 | P36: 0000 | Q36: 000 | R36: =CONCATENATE(I36,"-",J36,"-",K36,"-",L36,"-",M36,"-",N36,"-",O36,"-",P36,"-",Q36) -> ACU-041-411003-63101503-210-UO-000-0000-000
B37: Mktg. & Sales Cinema BCTV | C37: AV690 / 411408 | D37: AV690 | E37: 411408 | F37: ok | G37: 143 | H37: BCTV | I37: ACU | J37: 041 | K37: =E37 -> 411408 | L37: 63101503 | M37: =G37 -> 143 | O37: 000 | P37: 0000 | Q37: 000 | R37: =CONCATENATE(I37,"-",J37,"-",K37,"-",L37,"-",M37,"-",N37,"-",O37,"-",P37,"-",Q37) -> ACU-041-411408-63101503-143--000-0000-000
B38: Tienda Canon | Digital Marketing & Design | C38: AV670 / 460410 | D38: AV670 | E38: 460410 | F38: ok | G38: 172 | H38: E-commerce | I38: ACU | J38: 041 | K38: =E38 -> 460410 | L38: 63101503 | M38: =G38 -> 172 | N38: AA | O38: 000 | P38: 0000 | Q38: 000 | R38: =CONCATENATE(I38,"-",J38,"-",K38,"-",L38,"-",M38,"-",N38,"-",O38,"-",P38,"-",Q38) -> ACU-041-460410-63101503-172-AA-000-0000-000
B39: Canon Academy & Print Spot | C39: AV710 / 425103 | D39: AV710 | E39: 425103 | F39: Cambio en S21 | G39: 173 | H39: New Business | I39: ACU | J39: 041 | K39: =E39 -> 425103 | L39: 63101503 | M39: =G39 -> 173 | N39: AA | O39: 000 | P39: 0000 | Q39: 000 | R39: =CONCATENATE(I39,"-",J39,"-",K39,"-",L39,"-",M39,"-",N39,"-",O39,"-",P39,"-",Q39) -> ACU-041-425103-63101503-173-AA-000-0000-000
B40: Consumer Direct Sales | C40: AV700 / 411310 | D40: AV700 | E40: 411310 | F40: Cambio en S21 | G40: 173 | H40: New Business | I40: ACU | J40: 041 | K40: =E40 -> 411310 | L40: 63101503 | M40: =G40 -> 173 | N40: AA | O40: 000 | P40: 0000 | Q40: 000 | R40: =CONCATENATE(I40,"-",J40,"-",K40,"-",L40,"-",M40,"-",N40,"-",O40,"-",P40,"-",Q40) -> ACU-041-411310-63101503-173-AA-000-0000-000
...
